Workbook
Name SAVING: 'Cash and Bank Notes'!$C$31

Sheet Notes_Old
B1: NOTES:
A2: 1 | B2: Version | C2: 2
A3: 2 | B3: Date of version | C3: 44743
A4: 3 | B4: Report file name: Please replace the MMM-YYYY_XXXXXXX in the report filename (MLAG-MRT_V1_MMM-YYYY_XXXX) with first 3 letters of the month of the reporting date, the year and last 7 characters of the member's MLAG ID. E.g. MLAG-MRT_Dec-2014_0000001
A5: 4 | B5: Please select 'Report Code' from the drop down list in the first ('P&L') sheet and they will be populated on the other sheets. Report Code'MLAG-PR-UA' is to be selected for unaudited (UA) performance report (PR), which are currently expected to have quarterly reporting frequency. Report code 'MLAG-PR-A' is for reports that are based on audited figures and these are expected to be submitted annually. Also, please provide the other head information on the first ('P&L') sheet and they will be populated on the other sheets.
A6: 5 | B6: Reporting date: enter as Month and year ending the reporting period (e.g 12/2014 for quarter ending December 2014)
A7: 6 | B7: Reporting Period: enter the months and year covered in the reporting period (e.g October -December, 2015 for the October to December 2015 quarter )
A8: 7 | B8: The 'Regional Breakdown' sheet should be completed before the 'Portfolio Report' sheet and the 'Outreach & Social Performance' sheet so that data entered in the former will automatically populate relevant sections of the latter.
A9: 8 | B9: "Error" at the top of the Balance Sheet indicates that the Total Assets are not equal to Total Liabilities and Capital and there is need for checking and correction before submission.
A10: 9 | B10: Gross Loan Portfolio in the Balance Sheet must be equal to the Gross Loans Outstanding in the Portfolio Report, otherwise "Error" is indicated and correction is required.
A11: 10 | B11: Loan "Impairment Loss Allowance" (Loan loss reserves) in the Balnace Sheet (line 2.5) is linked to the Portfolio Report (line 3.15) - Total Actual Provisions made. Please input the actual loan loss provisions as at the reporting date in that section of the Portfolio Report and it will automatically reflect in the Balance sheet.
B13: Unique Code for File
B14: =C2&"-"&'Profit & Loss Statement'!C9&"-"&'Profit & Loss Statement'!C5&"-"&'Profit & Loss Statement'!C7 -> 2-2026- GCSCA-GT-0-0000288-JUNE
B16: Version Number
B17: =C2 -> 2

Sheet Errors Summary Sheet
A1: Doc Version | B1: 10
A2: Error Count Dashboard | C2: Error Description | F2: Cover Sheet | G2: Profit & Loss Statement | H2: Balance Sheet | I2: Cash and Bank Notes | J2: Investment Details | K2: Acc Receivables & Other Assets | L2: Borrowings | M2: Other Liabilities | N2: Portfolio Report | O2: Outreach & Social Performance | P2: Susu Savings/Deposit | Q2: Top Largest Exposure | R2: Ratios
A3: Cover Sheet | B3: ='Cover Sheet'!E1 -> 0 | C3: =IF(ISTEXT(F4),F4)&IF(ISTEXT(F5),F5)&IF(ISTEXT(F11),F11)&IF(ISTEXT(F12),F12)&IF(ISTEXT(F13),F13)&IF(ISTEXT(F15),F15)&IF(ISTEXT(F16),F16)
A4: Profit & Loss Statement | B4: ='Profit & Loss Statement'!E1 -> 0 | C4: =IF(ISTEXT(G4),G4)&IF(ISTEXT(G5),G5)&IF(ISTEXT(G11),G11)&IF(ISTEXT(G12),G12)&IF(ISTEXT(G13),G13)&IF(ISTEXT(G15),G15)&IF(ISTEXT(G16),G16)&IF(ISTEXT(G18),G18)&IF(ISTEXT(G21),G21) | F4: =IF('Cover Sheet'!D4=1, "Member Name Not Entered!; ", "") | G4: =IF('Profit & Loss Statement'!D4=1, "Member Name Not Entered!; ", "") | H4: =IF('Balance Sheet'!D4=1, "Member Name Not Entered!; ", "") | I4: =IF('Cash and Bank Notes'!D4=1, "Member Name Not Entered!; ", "") | J4: =IF('Investment Details'!D4=1, "Member Name Not Entered!; ", "") | K4: =IF('Acc Receivables & Other Assets'!D4=1, "Member Name Not Entered!; ", "") | L4: =IF(Borrowings!D4=1, "Member Name Not Entered!; ", "") | M4: =IF('Other Liabilities'!D4=1, "Member Name Not Entered!; ", "") | N4: =IF('Deposits Portfolio'!D4=1, "Member Name Not Entered!; ", "") | O4: =IF('Outreach & Social Performance'!D4=1, "Member Name Not Entered!; ", "") | P4: =IF('Deposits Portfolio'!D4=1, "Member Name Not Entered!; ", "") | Q4: =IF('Top Largest Depositors'!D4=1, "Member Name Not Entered!; ", "")
A5: Balance Sheet | B5: ='Balance Sheet'!E1 -> 0 | C5: =IF(ISTEXT(H4),H4)&IF(ISTEXT(H5),H5)&IF(ISTEXT(H11),H11)&IF(ISTEXT(H12),H12)&IF(ISTEXT(H13),H13)&IF(ISTEXT(H15),H15)&IF(ISTEXT(H16),H16)&IF(ISTEXT(H17),H17)&IF(ISTEXT(H18),H18)&IF(ISTEXT(H19),H19)&IF(ISTEXT(H21),H21)&IF(ISTEXT(H23),H23)&IF(ISTEXT(H24),H24)&IF(ISTEXT(H25),H25) | F5: =IF('Cover Sheet'!D5=1, "Member Code Not Entered!; ", "") | G5: =IF('Profit & Loss Statement'!D5=1, "Member Code Not Entered!; ", "") | H5: =IF('Balance Sheet'!D5=1, "Member Code Not Entered!; ", "") | I5: =IF('Cash and Bank Notes'!D5=1, "Member Code Not Entered!; ", "") | J5: =IF('Investment Details'!D5=1, "Member Code Not Entered!; ", "") | K5: =IF('Acc Receivables & Other Assets'!D5=1, "Member Code Not Entered!; ", "") | L5: =IF(Borrowings!D5=1, "Member Code Not Entered!; ", "") | M5: =IF('Other Liabilities'!D5=1, "Member Code Not Entered!; ", "") | N5: =IF('Deposits Portfolio'!D5=1, "Member Code Not Entered!; ", "") | O5: =IF('Outreach & Social Performance'!D5=1, "Member Code Not Entered!; ", "") | P5: =IF('Deposits Portfolio'!D5=1, "Member Code Not Entered!; ", "") | Q5: =IF('Top Largest Depositors'!D5=1, "Member Code Not Entered!; ", "")
A6: Cash and Bank Notes | B6: ='Cash and Bank Notes'!E1 -> 0 | C6: =IF(ISTEXT(I4),I4)&IF(ISTEXT(I5),I5)&IF(ISTEXT(I11),I11)&IF(ISTEXT(I12),I12)&IF(ISTEXT(I13),I13)&IF(ISTEXT(I15),I15)&IF(ISTEXT(I16),I16)&IF(ISTEXT(I17),I17)
A7: Investment Details | B7: ='Investment Details'!E1 -> 0 | C7: =IF(ISTEXT(J4),J4)&IF(ISTEXT(J5),J5)&IF(ISTEXT(J11),J11)&IF(ISTEXT(J12),J12)&IF(ISTEXT(J13),J13)&IF(ISTEXT(J15),J15)&IF(ISTEXT(J16),J16)
A8: Acc Receivables & Other Assets | B8: ='Acc Receivables & Other Assets'!E1 -> 0 | C8: =IF(ISTEXT(K4),K4)&IF(ISTEXT(K5),K5)&IF(ISTEXT(K11),K11)&IF(ISTEXT(K12),K12)&IF(ISTEXT(K13),K13)&IF(ISTEXT(K15),K15)&IF(ISTEXT(K16),K16)
A9: Borrowings | B9: =Borrowings!E1 -> 0 | C9: =IF(ISTEXT(L4),L4)&IF(ISTEXT(L5),L5)&IF(ISTEXT(L11),L11)&IF(ISTEXT(L12),L12)&IF(ISTEXT(L13),L13)&IF(ISTEXT(L15),L15)&IF(ISTEXT(L16),L16)&IF(ISTEXT(L17),L17)
A10: Other Liabilities | B10: ='Other Liabilities'!E1 -> 0 | C10: =IF(ISTEXT(M4),M4)&IF(ISTEXT(M5),M5)&IF(ISTEXT(M11),M11)&IF(ISTEXT(M12),M12)&IF(ISTEXT(M13),M13)&IF(ISTEXT(M15),M15)&IF(ISTEXT(M16),M16)
F11: =IF('Cover Sheet'!D6=1, "Return Code Not Entered!; ", "") | G11: =IF('Profit & Loss Statement'!D6=1, "Return Code Not Entered!; ", "") | H11: =IF('Balance Sheet'!D6=1, "Return Code Not Entered!; ", "") | I11: =IF('Cash and Bank Notes'!D6=1, "Return Code Not Entered!; ", "") | J11: =IF('Investment Details'!D6=1, "Return Code Not Entered!; ", "") | K11: =IF('Acc Receivables & Other Assets'!D6=1, "Return Code Not Entered!; ", "") | L11: =IF(Borrowings!D6=1, "Return Code Not Entered!; ", "") | M11: =IF('Other Liabilities'!D6=1, "Return Code Not Entered!; ", "") | N11: =IF(#REF!=1, "Return Code Not Entered!; ", "") -> #REF! | O11: =IF('Outreach & Social Performance'!D6=1, "Return Code Not Entered!; ", "") | P11: =IF('Deposits Portfolio'!D6=1, "Return Code Not Entered!; ", "") | Q11: =IF('Deposits Portfolio'!E6=1, "Return Code Not Entered!; ", "")
A12: Outreach & Social Performance | B12: ='Outreach & Social Performance'!E1 -> 0 | C12: =IF(ISTEXT(O4),O4)&IF(ISTEXT(O5),O5)&IF(ISTEXT(O11),O11)&IF(ISTEXT(O12),O12)&IF(ISTEXT(O13),O13)&IF(ISTEXT(O15),O15)&IF(ISTEXT(O16),O16)&IF(ISTEXT(O17),O17)&IF(ISTEXT(O19),O19) | F12: =IF('Cover Sheet'!D7=1, "Year not entered!; ","") | G12: =IF('Profit & Loss Statement'!D7=1, "Reporting Period Not Entered!; ","") | H12: =IF('Balance Sheet'!D7=1, "Reporting Period Not Entered!; ","") | I12: =IF('Cash and Bank Notes'!D7=1, "Reporting Period Not Entered!; ","") | J12: =IF('Investment Details'!D7=1, "Reporting Period Not Entered!; ","") | K12: =IF('Acc Receivables & Other Assets'!D7=1, "Reporting Period Not Entered!; ","") | L12: =IF(Borrowings!D7=1, "Reporting Period Not Entered!; ","") | M12: =IF('Other Liabilities'!D7=1, "Reporting Period Not Entered!; ","") | N12: =IF('Deposits Portfolio'!D7=1, "Reporting Period Not Entered!; ","") | O12: =IF('Outreach & Social Performance'!D7=1, "Reporting Period Not Entered!; ","") | P12: =IF('Deposits Portfolio'!D7=1, "Reporting Period Not Entered!; ","") | Q12: =IF('Top Largest Depositors'!D7=1, "Reporting Period Not Entered!; ","")
A13: Deposits Portfolio | B13: ='Deposits Portfolio'!E1 -> 0 | C13: =IF(ISTEXT(P4),P4)&IF(ISTEXT(P5),P5)&IF(ISTEXT(P11),P11)&IF(ISTEXT(P12),P12)&IF(ISTEXT(P13),P13)&IF(ISTEXT(P15),P15)&IF(ISTEXT(P16),P16)&IF(ISTEXT(P17),P17)&IF(ISTEXT(P18),P18) | F13: =IF('Cover Sheet'!D8=1, "Reporting Quarter Not Entered!; ","") | G13: =IF('Profit & Loss Statement'!D8=1, "Reporting Date Not Entered!; ","") | H13: =IF('Balance Sheet'!D8=1, "Reporting Date Not Entered!; ","") | I13: =IF('Cash and Bank Notes'!D8=1, "Reporting Date Not Entered!; ","") | J13: =IF('Investment Details'!D8=1, "Reporting Date Not Entered!; ","") | K13: =IF('Acc Receivables & Other Assets'!D8=1, "Reporting Date Not Entered!; ","") | L13: =IF(Borrowings!D8=1, "Reporting Date Not Entered!; ","") | M13: =IF('Other Liabilities'!D8=1, "Reporting Date Not Entered!; ","") | N13: =IF('Deposits Portfolio'!D8=1, "Reporting Date Not Entered!; ","") | O13: =IF('Outreach & Social Performance'!D8=1, "Reporting Date Not Entered!; ","") | P13: =IF('Deposits Portfolio'!D8=1, "Reporting Date Not Entered!; ","") | Q13: =IF('Top Largest Depositors'!D8=1, "Reporting Date Not Entered!; ","")
A14: Top Largest Exposure | B14: ='Top Largest Depositors'!E1 -> 0 | C14: =IF(ISTEXT(Q4),Q4)&IF(ISTEXT(Q5),Q5)&IF(ISTEXT(Q11),Q11)&IF(ISTEXT(Q12),Q12)&IF(ISTEXT(Q13),Q13)&IF(ISTEXT(Q15),Q15)&IF(ISTEXT(Q16),Q16)&IF(ISTEXT(Q17),Q17)
A15: Ratios | B15: =Ratios!G1 -> 0 | C15: =IF(R4 = "","",R4)&IF(R5 = "","",R5)&IF(R11 = "","",R11)&IF(R12 = "","",R12)&IF(R13 = "","",R13)&IF(R15 = "","",R15) | F15: =IF('Cover Sheet'!D9=1, "Reporting Date not populated!; ","") | G15: =IF('Profit & Loss Statement'!D9=1, "Year Not Entered!; ","") | H15: =IF('Balance Sheet'!D9=1, "Year Not Entered!; ","") | I15: =IF('Cash and Bank Notes'!D9=1, "Year Not Entered!; ","") | J15: =IF('Investment Details'!D9=1, "Year Not Entered!; ","") | K15: =IF('Acc Receivables & Other Assets'!D9=1, "Year Not Entered!; ","") | L15: =IF(Borrowings!D9=1, "Year Not Entered!; ","") | M15: =IF('Other Liabilities'!D9=1, "Year Not Entered!; ","") | N15: =IF('Deposits Portfolio'!D9=1, "Year Not Entered!; ","") | O15: =IF('Outreach & Social Performance'!D9=1, "Year Not Entered!; ","") | P15: =IF('Deposits Portfolio'!D9=1, "Year Not Entered!; ","") | Q15: =IF('Top Largest Depositors'!D9=1, "Year Not Entered!; ","")
F16: =IF('Cover Sheet'!D10=1, "Region not populated!; ","") | G16: =IF('Profit & Loss Statement'!D10=1, "Region not populated!; ","") | H16: =IF('Balance Sheet'!D20<>'Balance Sheet'!D36, "Total Assets MUST be equal to Total Liabilities and Equity!; ","") | I16: =IF('Cash and Bank Notes'!D10=1, "Region not populated!; ","") | J16: =IF('Investment Details'!D10=1, "Region not populated!; ","") | K16: =IF('Acc Receivables & Other Assets'!D10=1, "Region not populated!; ","") | L16: =IF(Borrowings!D10=1, "Region not populated!; ","") | M16: =IF('Other Liabilities'!D10=1, "Region not populated!; ","") | N16: =IF('Deposits Portfolio'!D10=1, "Region not populated!; ","") | O16: =IF('Outreach & Social Performance'!D10=1, "Region not populated!; ","") | P16: =IF('Deposits Portfolio'!D10=1, "Region not populated!; ","") | Q16: =IF('Top Largest Depositors'!D10=1, "Region not populated!; ","")
H17: =IF('Balance Sheet'!D13="", "Cash on hand and Due from Bank cannot be empty!; ","") | I17: =IF('Cash and Bank Notes'!C15=0, "Cash and bank Notes cannot be zero!; ","") | L17: =IF(Borrowings!J63>0, "Balance Outstanding cannot be more than Borrowed Amount!; ","") | O17: =IF('Outreach & Social Performance'!D22=0, "Number of Management staff cannot be empty!; ","") | P17: =IF('Deposits Portfolio'!E16<>'Deposits Portfolio'!E22, "Total Susu/deposit balance amount MUST be equal to Total Clients Susu Balances!; ","") | Q17: =IF('Top Largest Depositors'!E12=0, "Top Twenty (20) Largest Depositors sheet cannot be zero!; ","")
A18: NOTES | G18: =IF('Profit & Loss Statement'!D20="", "Depreciation and Amortization Expense cannot be empty!; ","") | H18: =IF('Balance Sheet'!D13=0, "Cash on hand and Due from Bank cannot be zero!; ","") | P18: =IF('Deposits Portfolio'!D16<>'Deposits Portfolio'!D22, "Number of Susu/Deposit balances MUST be equal to number of Total Clients!; ","")
A19: 1 | B19: The above shows the total number of errors in your quarterly prudential report. | G19: GCSCA-13-R-RB-OSP-PR-BS-PLS | H19: =IF('Balance Sheet'!D22=0, "Susu Savings/Deposit Portfolio cannot be empty!; ","") | O19: =IF('Outreach & Social Performance'!D15=0, "Number of Personnel(staff) cannot be empty!; ","")
A20: 2 | B20: The total number of Errors next to each line item should be zero (0)
A21: 3 | B21: Please ensure you submit the return to the Association only when number of errors is 0, otherwise it will be rejected by the system | G21: =IF('Profit & Loss Statement'!D20<0, "Depreciation and Amortization Expense cannot be negative!; ","") | H21: =IF('Balance Sheet'!D10=1, "Region not populated!; ","")
H23: =IF('Balance Sheet'!D17=0,"Fixed Asset cannot be Empty!; ","")
H24: =IF('Balance Sheet'!D18=0,"Accumulated Depreciation cannot be Empty!; ","")
H25: =IF('Balance Sheet'!D30=0,"Paid up capital cannot be Empty!; ","")

Sheet Cover Sheet
A1: GHANA CO-OPERATIVE SUSU COLLECTORS ASSOCIATION | E1: =SUM(D4:D10) -> 0 | F1: =IF(SUM(D4:D9)=0,"","Error!") | J1: JANUARY | K1: =TEXT(TODAY()-90, "YYYY") -> 2026
A2: MEMBERS REPORTING TEMPLATE | J2: FEBRUARY | K2: =TEXT(TODAY() -90 + 365, "YYYY") -> 2027
J3: MARCH | K3: =TEXT(TODAY() - 90 + 730, "YYYY") -> 2028
B4: MEMBER NAME: | C4: QUICK RETURNS SUSU ENTERPRISE | D4: =IF(C4="",1,IF(ISTEXT(C4),0,1))+IF(OR(ISNUMBER(LEFT(C4)),LEFT(C4)=" "),1,0) -> 0 | J4: APRIL
B5: MEMBERSHIP NUMBER: | C5: GCSCA-GT-0-0000288 | D5: =IF(C5="",1,IF(ISTEXT(C5),0,1))+IF(OR(ISNUMBER(LEFT(C5)),LEFT(C5)=" "),1,0) -> 0 | J5: MAY
B6: RETURN CODE: | C6: GCSCA-PR-UA | D6: =IF(C6="",1,IF(ISTEXT(C6),0,1)) -> 0 | J6: JUNE
B7: YEAR | C7: 2026 | D7: =IF(C7="",1,0) -> 0 | J7: JULY
B8: REPORTING MONTH | C8: JUNE | D8: =IF(C8="",1,IF(ISTEXT(C8),0,1)) -> 0 | J8: AUGUST
B9: REPORTING DATE | C9: =IF(SUM(C12:C13)=2, C11&" "&C14, "") -> July 2026 | D9: =IF(C9="",1, 0) -> 0 | J9: SEPTEMBER
B10: REGION | C10: Greater Accra-GA | D10: =IF(C10="",1, 0) -> 0 | J10: OCTOBER
C11: =IF(C8="January","February",IF(C8="February","March",IF(C8="March","April",IF(C8="April","May",IF(C8="May","June",IF(C8="June","July",IF(C8="July","August",IF(C8="August","September",IF(C8="September","October",IF(C8="October","November",IF(C8="November","December",IF(C8="December","January","")))))))))))) -> July | J11: NOVEMBER
C12: =IF(ISBLANK(C7), 0, 1) -> 1 | D12: Year | J12: DECEMBER
C13: =IF(ISBLANK(C8), 0,1) -> 1 | D13: Month
C14: =IF(C11="", "", IF(C11="January", C7+1, C7)) -> 2026
B18: ALL REGIONS
B19: Ahafo-AF
B20: Ashanti-AS
B21: Bono-BN
B22: Bono East-BE
B23: Central-CR
B24: Eastern-ER
B25: Greater Accra-GA
B26: North East-NE
B27: Northern-NR
B28: Oti-OT
B29: Savannah-SV
... B34: Western North-WN

Sheet Profit & Loss Statement
A1: ='Cover Sheet'!A1:D1 -> GHANA CO-OPERATIVE SUSU COLLECTORS ASSOCIATION | E1: =SUM(D4:D10) + IF(D20="",1,0) + IF(D20<0,1,0) -> 0 | F1: =IF(SUM(D4:D10)>0,"Error!",IF(D20="","Error!",IF(D20<0,"Error!","")))
A2: MEMBERS REPORTING TEMPLATE
B4: MEMBER NAME: | C4: =IF('Cover Sheet'!C4="", "", 'Cover Sheet'!C4) -> QUICK RETURNS SUSU ENTERPRISE | D4: =IF(C4="",1,IF(ISTEXT(C4),0,1))+IF(OR(ISNUMBER(LEFT(C4)),LEFT(C4)=" "),1,0) -> 0
B5: MEMBER CODE: | C5: =IF('Cover Sheet'!C5="", "", 'Cover Sheet'!C5) -> GCSCA-GT-0-0000288 | D5: =IF(C5="",1,IF(ISTEXT(C5),0,1))+IF(OR(ISNUMBER(LEFT(C5)),LEFT(C5)=" "),1,0) -> 0
B6: RETURN CODE: | C6: =IF('Cover Sheet'!C6="", "", 'Cover Sheet'!C6) -> GCSCA-PR-UA | D6: =IF(C6="",1,IF(ISTEXT(C6),0,1)) -> 0
B7: REPORTING PERIOD | C7: ='Cover Sheet'!C8 -> JUNE | D7: =IF(C7="",1,IF(ISTEXT(C7),0,1)) -> 0
B8: REPORTING DATE | C8: ='Cover Sheet'!C9 -> July 2026 | D8: =IF(C8="",1, 0) -> 0
B9: YEAR | C9: =IF('Cover Sheet'!C7="", "", 'Cover Sheet'!C7) -> 2026 | D9: =IF(C9="",1, 0) -> 0
B10: REGION | C10: =IF('Cover Sheet'!C10="", "", 'Cover Sheet'!C10) -> Greater Accra-GA | D10: =IF(C10="",1, 0) -> 0
A11: 1.0. | B11: INCOME STATEMENT | D11: Data for the reporting quarter
B12: Indicator | C12: Explanation (Definition of Indicator) | D12: GHS
A13: 1.1 | B13: Total Income from Commission | C13: How much money did you get out of commission during the reporting month? | D13: =D36 -> 1910
A14: 1.2 | B14: Interest from Investments | C14: How much interest did you receive from your bank account or your investments during the reporting month? | D14: =D44 -> 502.99
A15: 1.3 | B15: Other Operating Revenue | C15: Other income that is related to susu business within the reporting month.Eg. Sale of Passbook, Registration Fee etc. income out of mobile money should not be part of this. | D15: =D51 -> 0
A16: 1.4 | B16: Total Operating Revenue | C16: Line (1.1+1.2+1.3) | D16: =SUM(D13:D15) -> 2412.99
A17: 1.5 | B17: Financial Expense | D17: =D58 -> 0
B18: Operating Expense
A19: 1.6 | B19: Personnel Expense | C19: Includes staff salaries, bonuses, and benefits, as well as employment taxes. It also includes the cost of employee recruitment and initial orientation. This excludes staff training cost. | D19: =D95 -> 0
A20: 1.7 | B20: Depreciation and Amortization Expense | C20: The non-cash expense that allocates the purchase cost of an MFI's fixed assets over their useful economic life. Amortization is used for other tangible assets, such as software. | D20: 0 | E20: =IF(D20="","Error!", IF(D20<0, "Error!",""))
A21: 1.8 | B21: Other Administrative Expense | C21: Expenses that are related to susu business within the reporting month | D21: =D85 -> 2050
A22: 1.9 | B22: Total Operating Expense | C22: Sum(1.6+1.7+1.8) | D22: =SUM(D19:D21) -> 2050
A23: 1.1 | B23: Net Operating Income | C23: Net earnings from financial services . Line (1.4-1.5-1.9) | D23: =D16-D22-D17 -> 362.99
A24: 1.11 | B24: Non-Operating Revenue | C24: Income from products and services not directly related to core microfinance (money lending) operations.
A25: 1.12 | B25: Non- operating expense | C25: All expenses not directly related to the core susu operation, such as the cost of providing business development services or training, entered as a NEGATIVE number. This account also includes any exceptional losses and expenses.
A26: 1.13 | B26: Total Income Before Tax | C26: Line 1.10+(1.11+1.12) | D26: =D23+(D24+D25) -> 362.99
A27: 1.14 | B27: Tax | C27: Tax on profit
A28: 1.15 | B28: Net Income After Tax | C28: Line 1.13-1.14 | D28: =D26-D27 -> 362.99
B31: ANNEXURE A - TOTAL INCOME FROM COMMISION | C31: % OF TOTAL INCOME | D31: (CURRENT PERIOD - GHS)
A32: 1 | B32: Individual - Commission Income | C32: =IFERROR(D32/D16,0) -> 0.79154907 | D32: 1910
A33: 2 | B33: Group - Commission Income | C33: =IFERROR(D33/D16,0) -> 0
A34: 3 | B34: Private Enterprises - Commission Income | C34: =IFERROR(D34/D16,0) -> 0
A35: 4 | B35: Others | C35: =IFERROR(D35/D16,0) -> 0
B36: TOTAL | C36: =IFERROR(D36/D16,0) -> 0.79154907 | D36: =SUM(D32:D35) -> 1910
B39: ANNEXURE B - INTEREST REVENUE ON INVESTMENTS (DEPOSIT/PLACEMENTS) | C39: % OF TOTAL INCOME | D39: (CURRENT PERIOD - GHS)
A40: 1 | B40: Interest from savings/call accounts with banks/fin institutions | C40: =IFERROR(D40/D16,0) -> 0
A41: 2 | B41: Interest from Fixed deposits with banks/Fin. Insti | C41: =IFERROR(D41/D16,0) -> 0
A42: 3 | B42: Interest from Treasury and BOG bills | C42: =IFERROR(D42/D16,0) -> 0.20845093 | D42: 502.99
A43: 4 | B43: Others | C43: =IFERROR(D43/D16,0) -> 0
B44: TOTAL | C44: =IFERROR(D44/D16,0) -> 0.20845093 | D44: =SUM(D40:D43) -> 502.99
B47: ANNEXURE D - OTHER OPERATING INCOME | C47: % OF TOTAL INCOME | D47: (CURRENT PERIOD - GHS)
...

Sheet Balance Sheet
A1: ='Profit & Loss Statement'!A1:D1 -> GHANA CO-OPERATIVE SUSU COLLECTORS ASSOCIATION | E1: =SUM(D4:D10) + IF(D36=D20,0,1) + IF(D13="",1,0) + IF(D13=0,1,0) + IF(D17=0,1,0) + IF(D18=0,1,0) + IF(D30=0,1,0) -> 0 | F1: =IF(D36<>D20,"Error!",IF(SUM(D4:D10)>0,"Error!",IF(D13=0,"Error!",IF(D17=0,"Error!",IF(D18=0,"Error!",IF(D30=0,"Error!",""))))))
A2: ='Profit & Loss Statement'!A2:D2 -> MEMBERS REPORTING TEMPLATE
B4: MEMBER NAME: | C4: =IF('Profit & Loss Statement'!C4 = "", "", 'Profit & Loss Statement'!C4) -> QUICK RETURNS SUSU ENTERPRISE | D4: =IF(C4= "",1,0) -> 0
B5: MEMBER CODE: | C5: =IF('Profit & Loss Statement'!C5 = "", "", 'Profit & Loss Statement'!C5) -> GCSCA-GT-0-0000288 | D5: =IF(C5= "",1,0) -> 0
B6: RETURN CODE: | C6: =IF('Profit & Loss Statement'!C6 = "", "", 'Profit & Loss Statement'!C6) -> GCSCA-PR-UA | D6: =IF(C6= "",1,0) -> 0
B7: REPORTING PERIOD | C7: =IF('Profit & Loss Statement'!C7 = "", "", 'Profit & Loss Statement'!C7) -> JUNE | D7: =IF(C7= "",1,0) -> 0
B8: REPORTING DATE | C8: =IF('Profit & Loss Statement'!C8 = "", "", 'Profit & Loss Statement'!C8) -> July 2026 | D8: =IF(C8="",1, 0) -> 0
B9: YEAR | C9: ='Profit & Loss Statement'!C9 -> 2026 | D9: =IF(C9="",1, 0) -> 0
B10: REGION | C10: =IF('Cover Sheet'!C10="", "", 'Cover Sheet'!C10) -> Greater Accra-GA | D10: =IF(C10="",1, 0) -> 0
A11: 2.0 | B11: BALANCE SHEET
B12: Assets | D12: GHS
A13: 2.1 | B13: Cash on hand and Due from Bank | C13: How much of your clients' money did you have at the bank and in cash or Momo at the end of the reporting month? | D13: ='Cash and Bank Notes'!C15 -> 55895.41 | E13: =IF(D13="","Error!", IF(D13=0, "Error!", ""))
A14: 2.2 | B14: Short Term Investments | C14: How much of your clients' money is currently in short term investments as at the reporting date? (no SIF contributions) | D14: ='Investment Details'!D14 -> 3000
A15: 2.3 | B15: Accounts Receivable and other Assets | C15: Accounts receivable, notes receivables, and other receivables, net of any allowances for doubtful or uncollectible accounts. This includes all receivables other than client loan accounts, including interest receivable on non-funding liabilities such as mortgages. | D15: ='Acc Receivables & Other Assets'!D14 -> 0
A16: 2.4 | B16: Long term Investments | C16: Include investments that have a fixed maturity or payments that the MFI intents to hold to maturity. This item may include bonds or shares that the MFI plans to hold for 12 months or more or other financial assets available for sale but not considered loans, receivables, or Trade Investments. | D16: ='Investment Details'!D29 -> 0
A17: 2.5 | B17: Fixed Assets | C17: The cost or value of all physical property and property improvements, furniture, and equipment that the MFI currently uses. | D17: 74500 | E17: =IF(D17=0,"Error!","")
A18: 2.6 | B18: Accumulated Depreciation and Amortization(this figure should be negative) | C18: The sum of all depreciation expenses for Fixed Assets and the amortization of other tangible assets that have not yet been retired and removed from the balance sheet. Accumulated depreciation represents the reduction in value of Fixed Assets corresponding to the assets' remaining useful life. This contra asset account is expressed as a negative number. | D18: -3724.86 | E18: =IF(D18=0,"Error!","")
A19: 2.7 | B19: Net Fixed Assets | C19: Gross fixed assets less accumulated depreciation | D19: =D17+D18 -> 70775.14
A20: 2.8 | B20: Total Assets | D20: =ROUND((D13+D14+D15+D16+D19),2) -> 129670.55
B21: Liabilities
A22: 2.9 | B22: Susu Savings/Deposits | C22: Sum of all outstanding deposits (or clients' balances) at the day of reporting. Balances of all monies you owe your clients at the day of reporting, you haven't paid yet. | D22: ='Deposits Portfolio'!E16 -> 31255 | E22: =IF('Deposits Portfolio'!E16<>D22,"Error!","")
A23: 2.10 | B23: Short term Borrowing | C23: The principal balance of loans contracted from financial institutions / individuals which is payable within a year or 12 months | D23: =Borrowings!D15 -> 0
A24: 2.11 | B24: Long term borrowing | C24: The principal balance of loans contracted from financial institutions / individuals which is payable after a year | D24: =Borrowings!D40 -> 0
A25: 2.12 | B25: Total Borrowing | D25: =ROUND((D23+D24),2) -> 0
A26: 2.13 | B26: Interest payable on contracted loans | C26: Interest accrued on borrowings that fund operations.
A27: 2.14 | B27: Accounts Payable & Other Short-term Liabilities | C27: Other short-term liabilities due within 12 months, including tax and salary liabilities, payroll withholdings, and other accounts payable. | D27: ='Other Liabilities'!D14 -> 0
A28: 2.15 | B28: Total Liabilities | D28: =ROUND((D22+D25+D26+D27),2) -> 31255
B29: Equity
A30: 2.16 | B30: Paid-up Capital/Contributed Capital | C30: The value of capital paid by shareholders or members/owners net of any shares repurchased or capital repaid by owners (in the case of individual operators). | D30: 98052.56 | E30: =IF(D30=0,"Error!","")
A31: 2.17 | B31: Drawings | C31: The value of cash withdrawals taken out of the business by propritors/Proprietries for personal use. (This figure should be negative)
A32: 2.18 | B32: Income Surplus (Prior Period) | C32: The total value of Net Income (After Taxes and Before Donations) from prior periods, net of any dividends paid to shareholders or members.
A33: 2.19 | B33: Current Period P& L | C33: The total value of Net Income (After Taxes and Before Donations) from current period | D33: ='Profit & Loss Statement'!D28 -> 362.99
A34: 2.2 | B34: Other Reserves | C34: Any other reserves set aside for special purposes
A35: 2.21 | B35: Total Equity | D35: =ROUND((D30+D31+D32+D33+D34),2) -> 98415.55
A36: 2.22 | B36: Total Liabilities & Equity | D36: =ROUND((D28+D35),2) -> 129670.55 | E36: =IF(D36=D20,"","Error!")

Sheet Cash and Bank Notes
A1: ='Cover Sheet'!A1:D1 -> GHANA CO-OPERATIVE SUSU COLLECTORS ASSOCIATION | E1: =SUM(D4:D10) + IF(C15=0,1,0) -> 0 | F1: =IF(SUM(D4:D10)>0,"Error!", IF(C15=0,"Error!", ""))
A2: MEMBERS REPORTING TEMPLATE
B4: MEMBER NAME: | C4: =IF('Cover Sheet'!C4="", "", 'Cover Sheet'!C4) -> QUICK RETURNS SUSU ENTERPRISE | D4: =IF(C4="",1,IF(ISTEXT(C4),0,1))+IF(OR(ISNUMBER(LEFT(C4)),LEFT(C4)=" "),1,0) -> 0
B5: MEMBER CODE: | C5: =IF('Cover Sheet'!C5="", "", 'Cover Sheet'!C5) -> GCSCA-GT-0-0000288 | D5: =IF(C5="",1,IF(ISTEXT(C5),0,1))+IF(OR(ISNUMBER(LEFT(C5)),LEFT(C5)=" "),1,0) -> 0
B6: RETURN CODE: | C6: =IF('Cover Sheet'!C6="", "", 'Cover Sheet'!C6) -> GCSCA-PR-UA | D6: =IF(C6="",1,IF(ISTEXT(C6),0,1)) -> 0
B7: REPORTING PERIOD | C7: ='Balance Sheet'!C7 -> JUNE | D7: =IF(C7="",1,IF(ISTEXT(C7),0,1)) -> 0
B8: REPORTING DATE | C8: ='Cover Sheet'!C9 -> July 2026 | D8: =IF(C8="",1, 0) -> 0
B9: YEAR | C9: =IF('Cover Sheet'!C7="", "", 'Cover Sheet'!C7) -> 2026 | D9: =IF(C9="",1, 0) -> 0
B10: REGION | C10: =IF('Cover Sheet'!C10="", "", 'Cover Sheet'!C10) -> Greater Accra-GA | D10: =IF(C10="",1, 0) -> 0
A12: A | B12: Cash on Hand | C12: =+C21 -> 0
A13: B | B13: Electronic Cash | C13: =+C28 -> 0
A14: C | B14: Balances with Banks/Financial Institutions | C14: =+C43 -> 55895.41
B15: Grand Total | C15: =SUM(C12:C14) -> 55895.41 | D15: =IF(C15="","Error!", IF(C15=0, "Error!", ""))
A17: A | B17: Cash | C17: Amount (GHS)
A18: 1 | B18: Vault
A19: 2 | B19: Petty Cash
A20: 3 | B20: Others
B21: Total | C21: =C18+C19+C20 -> 0
A23: B | B23: Electronic Cash | C23: Amount (GHS)
A24: 1 | B24: MTN MoMo
A25: 2 | B25: Vodafone/Telecel Cash
A26: 3 | B26: AT Cash
A27: 4 | B27: Others
B28: Total | C28: =C24+C25+C27 -> 0
A30: C | B30: Banks/Financial Institutions
A31: No. | B31: Name of Bank/Financial Institution | C31: Amount (GHS) | D31: Account Type
A32: 1 | B32: ECOBANK | C32: 55895.41 | D32: SAVINGS
A33: 2
A34: 3
A35: 4
A36: 5
A37: 6
A38: 7
A39: 8
A40: 9
A41: 10
A42: 11
B43: Total | C43: =+SUM(C31:C42) -> 55895.41

Sheet Investment Details
A1: ='Cover Sheet'!A1:D1 -> GHANA CO-OPERATIVE SUSU COLLECTORS ASSOCIATION | E1: =SUM(D4:D10) -> 0 | F1: =IF(SUM(D4:D10)>0, "Error!", "")
A2: MEMBERS REPORTING TEMPLATE
B4: MEMBER NAME: | C4: =IF('Cover Sheet'!C4="", "", 'Cover Sheet'!C4) -> QUICK RETURNS SUSU ENTERPRISE | D4: =IF(C4="",1,IF(ISTEXT(C4),0,1))+IF(OR(ISNUMBER(LEFT(C4)),LEFT(C4)=" "),1,0) -> 0
B5: MEMBER CODE: | C5: =IF('Cover Sheet'!C5="", "", 'Cover Sheet'!C5) -> GCSCA-GT-0-0000288 | D5: =IF(C5="",1,IF(ISTEXT(C5),0,1))+IF(OR(ISNUMBER(LEFT(C5)),LEFT(C5)=" "),1,0) -> 0
B6: RETURN CODE: | C6: =IF('Cover Sheet'!C6="", "", 'Cover Sheet'!C6) -> GCSCA-PR-UA | D6: =IF(C6="",1,IF(ISTEXT(C6),0,1)) -> 0
B7: REPORTING PERIOD | C7: ='Cash and Bank Notes'!C7 -> JUNE | D7: =IF(C7="",1,IF(ISTEXT(C7),0,1)) -> 0
B8: REPORTING DATE | C8: ='Cover Sheet'!C9 -> July 2026 | D8: =IF(C8="",1, 0) -> 0
B9: YEAR | C9: =IF('Cover Sheet'!C7="", "", 'Cover Sheet'!C7) -> 2026 | D9: =IF(C9="",1, 0) -> 0
B10: REGION | C10: =IF('Cover Sheet'!C10="", "", 'Cover Sheet'!C10) -> Greater Accra-GA | D10: =IF(C10="",1, 0) -> 0
A12: Item No. | B12: Short Term Investment
A13: A | B13: Name of Institution | C13: Investment Type | D13: Amount (GHS) | E13: Placement Date | F13: Maturity Date | G13: Interest Rate % (p. a.)
A14: Sub-Total A | D14: =SUM(D15:D25) -> 3000
A15: 1 | B15: ECOBANK | C15: TREASURY BILL | D15: 3000
A16: 2
A17: 3
A18: 4
A19: 5
A20: 6
A21: 7
A22: 8
A23: 9
A24: 10
A25: 11
A27: Item No. | B27: Long Term Investment
A28: B | B28: Name of Institution | C28: Investment Type | D28: Amount (GHS) | E28: Placement Date | F28: Maturity Date | G28: Interest Rate % (p. a.)
A29: Sub-Total B | D29: =SUM(D30:D40) -> 0
A30: 1
A31: 2
A32: 3
A33: 4
A34: 5
A35: 6
A36: 7
A37: 8
A38: 9
A39: 10
A40: 11
G50: 5

Sheet Acc Receivables & Other Assets
A1: ='Cover Sheet'!A1:D1 -> GHANA CO-OPERATIVE SUSU COLLECTORS ASSOCIATION | E1: =SUM(D4:D10) -> 0 | F1: =IF(SUM(D4:D10)=0,"","Error!")
A2: MEMBERS REPORTING TEMPLATE
B4: MEMBER NAME: | C4: =IF('Cover Sheet'!C4="", "", 'Cover Sheet'!C4) -> QUICK RETURNS SUSU ENTERPRISE | D4: =IF(C4="",1,IF(ISTEXT(C4),0,1))+IF(OR(ISNUMBER(LEFT(C4)),LEFT(C4)=" "),1,0) -> 0
B5: MEMBER CODE: | C5: =IF('Cover Sheet'!C5="", "", 'Cover Sheet'!C5) -> GCSCA-GT-0-0000288 | D5: =IF(C5="",1,IF(ISTEXT(C5),0,1))+IF(OR(ISNUMBER(LEFT(C5)),LEFT(C5)=" "),1,0) -> 0
B6: RETURN CODE: | C6: =IF('Cover Sheet'!C6="", "", 'Cover Sheet'!C6) -> GCSCA-PR-UA | D6: =IF(C6="",1,IF(ISTEXT(C6),0,1)) -> 0
B7: REPORTING PERIOD | C7: ='Investment Details'!C7 -> JUNE | D7: =IF(C7="",1,IF(ISTEXT(C7),0,1)) -> 0
B8: REPORTING DATE | C8: ='Cover Sheet'!C9 -> July 2026 | D8: =IF(C8="",1, 0) -> 0
B9: YEAR | C9: =IF('Cover Sheet'!C7="", "", 'Cover Sheet'!C7) -> 2026 | D9: =IF(C9="",1, 0) -> 0
B10: REGION | C10: =IF('Cover Sheet'!C10="", "", 'Cover Sheet'!C10) -> Greater Accra-GA | D10: =IF(C10="",1, 0) -> 0
A12: Account Receivables & Other Assets/Prepayments
A13: No. | B13: Breakdown | C13: % To Total | D13: Amount (GHS)
A14: Total | C14: =IFERROR(D14/D14,0) -> 0 | D14: =SUM(D15:D26) -> 0
A15: 1 | B15: RENT PREPAID | C15: =IFERROR(D15/D$14,0) -> 0
A16: 2 | B16: INSURANCE PREPAID | C16: =IFERROR(D16/D$14,0) -> 0
A17: 3 | C17: =IFERROR(D17/D$14,0) -> 0
A18: 4 | C18: =IFERROR(D18/D$14,0) -> 0
A19: 5 | C19: =IFERROR(D19/D$14,0) -> 0
A20: 6 | C20: =IFERROR(D20/D$14,0) -> 0
A21: 7 | C21: =IFERROR(D21/D$14,0) -> 0
A22: 8 | C22: =IFERROR(D22/D$14,0) -> 0
A23: 9 | C23: =IFERROR(D23/D$14,0) -> 0
A24: 10 | C24: =IFERROR(D24/D$14,0) -> 0
A25: 11 | C25: =IFERROR(D25/D$14,0) -> 0
A26: 12 | C26: =IFERROR(D26/D$14,0) -> 0

Sheet Borrowings
A1: ='Cover Sheet'!A1:D1 -> GHANA CO-OPERATIVE SUSU COLLECTORS ASSOCIATION | E1: =SUM(D4:D10) + IF(D15>C15,1,0)+ IF(D16>C16,1,0)+ IF(D17>C17,1,0)+ IF(D18>C18,1,0)+ IF(D19>C19,1,0)+ IF(D20>C20,1,0)+ IF(D21>C21,1,0)+ IF(D22>C22,1,0)+ IF(D23>C23,1,0)+ IF(D24>C24,1,0)+ IF(D25>C25,1,0)+ IF(D26>C26,1,0)+ IF(D27>C27,1,0)+ IF(D28>C28,1,0)+ IF(D29>C29,1,0)+ IF(D30>C30,1,0)+ IF(D31>C31,1,0)+ IF(D32>C32,1,0)+ IF(D33>C33,1,0)+ IF(D34>C34,1,0)+ IF(D35>C35,1,0)+ IF(D40>C40,1,0)+ IF(D41>C41,1,0)+ IF(D42>C42,1,0)+ IF(D43>C43,1,0)+ IF(D44>C44,1,0)+ IF(D45>C45,1,0)+ IF(D46>C46,1,0)+ IF(D47>C47,1,0)+ IF(D48>C48,1,0)+ IF(D49>C49,1,0)+ IF(D50>C50,1,0)+ IF(D51>C51,1,0)+ IF(D52>C52,1,0)+ IF(D53>C53,1,0)+ IF(D54>C54,1,0)+ IF(D55>C55,1,0)+ IF(D56>C56,1,0)+ IF(D57>C57,1,0)+ IF(D58>C58,1,0)+ IF(D59>C59,1,0)+ IF(D60>C60,1,0) -> 0 | F1: =IF(SUM(D4:D10)=0,"","Error!")
A2: MEMBERS REPORTING TEMPLATE
B4: MEMBER NAME: | C4: =IF('Cover Sheet'!C4="", "", 'Cover Sheet'!C4) -> QUICK RETURNS SUSU ENTERPRISE | D4: =IF(C4="",1,IF(ISTEXT(C4),0,1))+IF(OR(ISNUMBER(LEFT(C4)),LEFT(C4)=" "),1,0) -> 0
B5: MEMBER CODE: | C5: =IF('Cover Sheet'!C5="", "", 'Cover Sheet'!C5) -> GCSCA-GT-0-0000288 | D5: =IF(C5="",1,IF(ISTEXT(C5),0,1))+IF(OR(ISNUMBER(LEFT(C5)),LEFT(C5)=" "),1,0) -> 0
B6: RETURN CODE: | C6: =IF('Cover Sheet'!C6="", "", 'Cover Sheet'!C6) -> GCSCA-PR-UA | D6: =IF(C6="",1,IF(ISTEXT(C6),0,1)) -> 0
B7: REPORTING PERIOD | C7: ='Acc Receivables & Other Assets'!C7 -> JUNE | D7: =IF(C7="",1,IF(ISTEXT(C7),0,1)) -> 0
B8: REPORTING DATE | C8: ='Cover Sheet'!C9 -> July 2026 | D8: =IF(C8="",1, 0) -> 0
B9: YEAR | C9: =IF('Cover Sheet'!C7="", "", 'Cover Sheet'!C7) -> 2026 | D9: =IF(C9="",1, 0) -> 0
B10: REGION | C10: =IF('Cover Sheet'!C10="", "", 'Cover Sheet'!C10) -> Greater Accra-GA | D10: =IF(C10="",1, 0) -> 0
A12: GRAND TOTAL (A + B) | D12: =SUM(D15,D40) -> 0
A13: Item No. | B13: Short Term Borrowings
A14: A | B14: Name of Institution/Person | C14: Borrowed Amount (GHS) | D14: Principal Balance Outstanding (GHS) | E14: Agreement Date | F14: Expiry Date | G14: Interest Rate (p. a.)
A15: Sub-Total A | C15: =SUM(C16:C35) -> 0 | D15: =SUM(D16:D35) -> 0 | H15: =IF(D15>C15, "Error!", "") | J15: =IF(D15>C15, 1, 0) -> 0
A16: 1 | H16: =IF(D16>C16, "Error!", "") | J16: =IF(D16>C16, 1, 0) -> 0
A17: 2 | H17: =IF(D17>C17, "Error!", "") | J17: =IF(D17>C17, 1, 0) -> 0
A18: 3 | H18: =IF(D18>C18, "Error!", "") | J18: =IF(D18>C18, 1, 0) -> 0
A19: 4 | H19: =IF(D19>C19, "Error!", "") | J19: =IF(D19>C19, 1, 0) -> 0
A20: 5 | H20: =IF(D20>C20, "Error!", "") | J20: =IF(D20>C20, 1, 0) -> 0
A21: 6 | H21: =IF(D21>C21, "Error!", "") | J21: =IF(D21>C21, 1, 0) -> 0
A22: 7 | H22: =IF(D22>C22, "Error!", "") | J22: =IF(D22>C22, 1, 0) -> 0
A23: 8 | H23: =IF(D23>C23, "Error!", "") | J23: =IF(D23>C23, 1, 0) -> 0
A24: 9 | H24: =IF(D24>C24, "Error!", "") | J24: =IF(D24>C24, 1, 0) -> 0
A25: 10 | H25: =IF(D25>C25, "Error!", "") | J25: =IF(D25>C25, 1, 0) -> 0
A26: 11 | H26: =IF(D26>C26, "Error!", "") | J26: =IF(D26>C26, 1, 0) -> 0
A27: 12 | H27: =IF(D27>C27, "Error!", "") | J27: =IF(D27>C27, 1, 0) -> 0
... A35: 20 | H35: =IF(D35>C35, "Error!", "") | J35: =IF(D35>C35, 1, 0) -> 0
B38: Long Term Borrowings
A39: B | B39: Name of Institution | C39: Borrowed Amount (GHS) | D39: Principal Balance Outstanding (GHS) | E39: Agreement Date | F39: Expiry Date | G39: Interest Rate (p. a.)
A40: Sub-Total B | C40: =SUM(C41:C60) -> 0 | D40: =SUM(D41:D60) -> 0 | H40: =IF(D40>C40, "Error!", "") | J40: =IF(D40>C40, 1, 0) -> 0
A41: 1 | H41: =IF(D41>C41, "Error!", "") | J41: =IF(D41>C41, 1, 0) -> 0
A42: 2 | H42: =IF(D42>C42, "Error!", "") | J42: =IF(D42>C42, 1, 0) -> 0
A43: 3 | H43: =IF(D43>C43, "Error!", "") | J43: =IF(D43>C43, 1, 0) -> 0
A44: 4 | H44: =IF(D44>C44, "Error!", "") | J44: =IF(D44>C44, 1, 0) -> 0
A45: 5 | H45: =IF(D45>C45, "Error!", "") | J45: =IF(D45>C45, 1, 0) -> 0
A46: 6 | H46: =IF(D46>C46, "Error!", "") | J46: =IF(D46>C46, 1, 0) -> 0
A47: 7 | H47: =IF(D47>C47, "Error!", "") | J47: =IF(D47>C47, 1, 0) -> 0
A48: 8 | H48: =IF(D48>C48, "Error!", "") | J48: =IF(D48>C48, 1, 0) -> 0
A49: 9 | H49: =IF(D49>C49, "Error!", "") | J49: =IF(D49>C49, 1, 0) -> 0
A50: 10 | H50: =IF(D50>C50, "Error!", "") | J50: =IF(D50>C50, 1, 0) -> 0
A51: 11 | H51: =IF(D51>C51, "Error!", "") | J51: =IF(D51>C51, 1, 0) -> 0
...

Sheet Other Liabilities
A1: ='Cover Sheet'!A1:D1 -> GHANA CO-OPERATIVE SUSU COLLECTORS ASSOCIATION | E1: =SUM(D4:D10) -> 0 | F1: =IF(SUM(D4:D10)=0,"","Error!")
A2: MEMBERS REPORTING TEMPLATE
B4: MEMBER NAME: | C4: =IF('Cover Sheet'!C4="", "", 'Cover Sheet'!C4) -> QUICK RETURNS SUSU ENTERPRISE | D4: =IF(C4="",1,IF(ISTEXT(C4),0,1))+IF(OR(ISNUMBER(LEFT(C4)),LEFT(C4)=" "),1,0) -> 0
B5: MEMBER CODE: | C5: =IF('Cover Sheet'!C5="", "", 'Cover Sheet'!C5) -> GCSCA-GT-0-0000288 | D5: =IF(C5="",1,IF(ISTEXT(C5),0,1))+IF(OR(ISNUMBER(LEFT(C5)),LEFT(C5)=" "),1,0) -> 0
B6: RETURN CODE: | C6: =IF('Cover Sheet'!C6="", "", 'Cover Sheet'!C6) -> GCSCA-PR-UA | D6: =IF(C6="",1,IF(ISTEXT(C6),0,1)) -> 0
B7: REPORTING PERIOD | C7: ='Acc Receivables & Other Assets'!C7 -> JUNE | D7: =IF(C7="",1,IF(ISTEXT(C7),0,1)) -> 0
B8: REPORTING DATE | C8: ='Cover Sheet'!C9 -> July 2026 | D8: =IF(C8="",1, 0) -> 0
B9: YEAR | C9: =IF('Cover Sheet'!C7="", "", 'Cover Sheet'!C7) -> 2026 | D9: =IF(C9="",1, 0) -> 0
B10: REGION | C10: =IF('Cover Sheet'!C10="", "", 'Cover Sheet'!C10) -> Greater Accra-GA | D10: =IF(C10="",1, 0) -> 0
A12: Account Payables and Other Liabilities/Accruals
A13: No. | B13: Detail | C13: % To Total | D13: Amount (GHS)
A14: Total | C14: =IFERROR(D14/D14,0) -> 0 | D14: =SUM(D15:D26) -> 0
A15: 1 | B15: SSNIT TIER ONE | C15: =IFERROR(D15/D$14,0) -> 0
A16: 2 | B16: SECOND TIER | C16: =IFERROR(D16/D$14,0) -> 0
A17: 3 | B17: PAYE | C17: =IFERROR(D17/D$14,0) -> 0
A18: 4 | B18: STAFF SALARY OUTSTANDING | C18: =IFERROR(D18/D$14,0) -> 0
A19: 5 | B19: STAFF WELFARE | C19: =IFERROR(D19/D$14,0) -> 0
A20: 6 | B20: INCOME TAX_PROVISION | C20: =IFERROR(D20/D$14,0) -> 0
A21: 7 | B21: WITHOLDING TAX | C21: =IFERROR(D21/D$14,0) -> 0
A22: 8 | B22: Other Payables | C22: =IFERROR(D22/D$14,0) -> 0
A23: 9 | C23: =IFERROR(D23/D$14,0) -> 0
A24: 10 | C24: =IFERROR(D24/D$14,0) -> 0
A25: 11 | C25: =IFERROR(D25/D$14,0) -> 0
A26: 12 | C26: =IFERROR(D26/D$14,0) -> 0

Sheet Outreach & Social Performance
A1: ='Profit & Loss Statement'!A1:D1 -> GHANA CO-OPERATIVE SUSU COLLECTORS ASSOCIATION | E1: =SUM(D4:D10) +IF(D15=0,1,0)+IF(D22=0,1,0)+IF(D18=0,1,0) -> 0 | F1: =IF(SUM(D4:D10)>0,"Error!", IF(D15=0,"Error!", IF(D16=0,"Error!", "")))
A2: ='Profit & Loss Statement'!A2:D2 -> MEMBERS REPORTING TEMPLATE
B4: MEMBER NAME: | C4: =IF('Profit & Loss Statement'!C4 = "", "", 'Profit & Loss Statement'!C4) -> QUICK RETURNS SUSU ENTERPRISE | D4: =IF(C4="",1,IF(ISTEXT(C4),0,1))+IF(OR(ISNUMBER(LEFT(C4)),LEFT(C4)=" "),1,0) -> 0
B5: MEMBER CODE: | C5: =IF('Profit & Loss Statement'!C5 = "", "", 'Profit & Loss Statement'!C5) -> GCSCA-GT-0-0000288 | D5: =IF(C5="",1,IF(ISTEXT(C5),0,1))+IF(OR(ISNUMBER(LEFT(C5)),LEFT(C5)=" "),1,0) -> 0
B6: RETURN CODE: | C6: =IF('Profit & Loss Statement'!C6 = "", "", 'Profit & Loss Statement'!C6) -> GCSCA-PR-UA | D6: =IF(C6="",1,IF(ISTEXT(C6),0,1)) -> 0
B7: REPORTING PERIOD | C7: =IF('Profit & Loss Statement'!C7 = "", "", 'Profit & Loss Statement'!C7) -> JUNE | D7: =IF(C7="",1,IF(ISTEXT(C7),0,1)) -> 0
B8: REPORTING DATE | C8: =IF('Profit & Loss Statement'!C8 = "", "", 'Profit & Loss Statement'!C8) -> July 2026 | D8: =IF(C8="",1, 0) -> 0
B9: YEAR | C9: ='Profit & Loss Statement'!C9 -> 2026 | D9: =IF(C9="",1, 0) -> 0
B10: REGION | C10: =IF('Cover Sheet'!C10="", "", 'Cover Sheet'!C10) -> Greater Accra-GA | D10: =IF(C10="",1, 0) -> 0
A11: 5.0 | B11: OUTREACH & SOCIAL PERFORMANCE DATA
A12: 5.1 | B12: Total number of new clients for this month - female | D12: 0
A13: 5.2 | B13: Total number of new clients for this month - male | D13: 0
B14: Details about Staff
A15: 5.3 | B15: Number of Personnel (Staff) | C15: including the owner, the agents and office staff | D15: 3 | E15: =IF(D15="", "Error!", "") | I15: =IF(D15="", 1, 0) -> 0
A16: 5.4 | B16: Number of Female Personnel (Staff) | C16: including the owner, the agents and office staff | D16: 1 | E16: =IF(D16="", "Error!", "") | I16: =IF(D16="", 1, 0) -> 0
A17: 5.5 | B17: Number of Male Personnel (Staff) | C17: including the owner, the agents and office staff | D17: 2
A18: 5.6 | B18: Number of Mobile Bankers | C18: Out of the total number of employees, how many are agents / mobile bankers? | D18: 2 | E18: =IF(D18="", "Error!", "") | I18: =IF(D18="", 1, 0) -> 0
A19: 5.7 | B19: Number of new staff recruited during the period | D19: 0
A20: 5.8 | B20: Number of staff who resigned during the period | D20: 0
B21: Details about Management Staff
A22: 5.9 | B22: Number of Staff in Management position | D22: 1 | E22: =IF(D22="", "Error!", "") | I22: =IF(D22="", 1, 0) -> 0
A23: 5.10 | B23: Number of Female Staff in management position | D23: 0 | E23: =IF(D23="", "Error!", "") | I23: =IF(D23="", 1, 0) -> 0
A24: 5.11 | B24: Number of male Staff in management position | D24: 1
A25: 5.12 | B25: Number of management meetings held during the period | D25: 0 | E25: =IF(D25="", "Error!", "") | I25: =IF(D25="", 1, 0) -> 0
A26: 5.13 | B26: Number of Advisory committee members | D26: 3 | E26: =IF(D26="", "Error!", "") | I26: =IF(D26="", 1, 0) -> 0
A27: 5.14 | B27: Number of Advisory committee meetings held during the period | D27: 0 | E27: =IF(D27="", "Error!", "") | I27: =IF(D27="", 1, 0) -> 0

Sheet Deposits Portfolio
A1: ='Profit & Loss Statement'!A1:D1 -> GHANA CO-OPERATIVE SUSU COLLECTORS ASSOCIATION | E1: =SUM(D4:D10) + IF(D16=D22,0,1) + IF(E16=E22,0,1) -> 0 | F1: =IF(SUM(D4:D10)>0,"Error!", IF(D15=0,"Error!", IF(D16=0,"Error!", "")))
A2: ='Profit & Loss Statement'!A2:D2 -> MEMBERS REPORTING TEMPLATE
B4: MEMBER NAME: | C4: =IF('Profit & Loss Statement'!C4 = "", "", 'Profit & Loss Statement'!C4) -> QUICK RETURNS SUSU ENTERPRISE | D4: =IF(C4="",1,IF(ISTEXT(C4),0,1))+IF(OR(ISNUMBER(LEFT(C4)),LEFT(C4)=" "),1,0) -> 0
B5: MEMBER CODE: | C5: =IF('Profit & Loss Statement'!C5 = "", "", 'Profit & Loss Statement'!C5) -> GCSCA-GT-0-0000288 | D5: =IF(C5="",1,IF(ISTEXT(C5),0,1))+IF(OR(ISNUMBER(LEFT(C5)),LEFT(C5)=" "),1,0) -> 0
B6: RETURN CODE: | C6: =IF('Profit & Loss Statement'!C6 = "", "", 'Profit & Loss Statement'!C6) -> GCSCA-PR-UA | D6: =IF(C6="",1,IF(ISTEXT(C6),0,1)) -> 0
B7: REPORTING PERIOD | C7: =IF('Profit & Loss Statement'!C7 = "", "", 'Profit & Loss Statement'!C7) -> JUNE | D7: =IF(C7="",1,IF(ISTEXT(C7),0,1)) -> 0
B8: REPORTING DATE | C8: =IF('Profit & Loss Statement'!C8 = "", "", 'Profit & Loss Statement'!C8) -> July 2026 | D8: =IF(C8="",1, 0) -> 0
B9: YEAR | C9: ='Profit & Loss Statement'!C9 -> 2026 | D9: =IF(C9="",1, 0) -> 0
B10: REGION | C10: =IF('Profit & Loss Statement'!C10 = "", "", 'Profit & Loss Statement'!C10) -> Greater Accra-GA | D10: =IF(C10="",1, 0) -> 0
B12: PARAMETERS/ INDICATORS | C12: DESCRIPTION | D12: TOTAL
A13: 1.0 | B13: DEPOSITS PORTFOLIO ACTIVITY | C13: DEFINITION | D13: NUMBER OF CLIENTS | E13: VALUE (GHS)
A14: 1.1 | B14: Total Client deposits mobilised this month | C14: The number and value of How much money have you mobilized from all of your clients during that particular month of reporting? | D14: 380 | E14: 57718
A15: 1.2 | B15: Total Withdrawals paid to clients this month | C15: The total amount of money you have paid to your clients within the reporting month. | D15: 50 | E15: 15000
A16: 1.3 | B16: Total Susu/savings balances as at reporting date | C16: Sum of all outstanding deposits (or clients' balances) at the day of reporting. Balances of all monies you owe your clients at the day of reporting, you haven't paid yet. Enter the number and Value | D16: 380 | E16: 31255 | F16: =IF(D16<>D22,"Error!", IF(E16<>E22, "Error!", ""))
A17: 1.4 | B17: Total Females Savings/Susu Portfolio as at the reporting date | D17: 290 | E17: 23852.49
A18: 1.5 | B18: Total Males Savings/Susu Portfolio as at the reporting date | D18: 90 | E18: 7402.51
A19: 1.7 | B19: Total Dormant balances as at reporting date | C19: If you have dormant clients what is the total amount of their money that you are keeping? | D19: 0 | E19: 0
A21: 2.0 | B21: OUTREACH & SOCIAL PERFORMANCE DATA | D21: NUMBER OF CLIENTS | E21: VALUE (GHS)
A22: 2.1 | B22: Total Number of Clients | C22: The number of depositors/susu savers, who are currently saving with the Susu enterprise. Individuals who have multiple accounts with the susu enterprise should be counted as a single client. | D22: =+D17+D18 -> 380 | E22: =+E17+E18 -> 31255 | F22: =IF(E22=E16," ","Error!")
A23: 2.2 | B23: Total Number of female clients | C23: The number of female depositors/susu savers, who are currently saving with the Susu enterprise. Individuals who have multiple accounts with the susu enterprise should be counted as a single client. | D23: =+D17 -> 290 | E23: =+E17 -> 23852.49
A24: 2.3 | B24: Total Number of male clients | C24: The number of male depositors/susu savers, who are currently saving with the Susu enterprise. Individuals who have multiple accounts with the susu enterprise should be counted as a single client. | D24: =+D18 -> 90 | E24: =+E18 -> 7402.51
A25: 2.4 | B25: Total number of clients dropping out (permanently closed accounts) this month
A26: 2.5 | B26: Average Susu Mobilised in the Month (GHS) | C26: Value of Susu mobilized in the month divided by the number of susu savers. | E26: =IFERROR(ROUND((E14/D14),2), 0) -> 151.89
A27: 2.6 | B27: Average susu savings balance per client as at reporting date (GHS) | C27: Value of susu savings balances divided by the number of susu savers. | E27: =IFERROR(ROUND((E16/D16),2), 0) -> 82.25
A28: 2.7 | B28: Total Number & Value of youth depositors (18-35 years) | C28: Total Number of youth savers (18-35 years) during the reporting period
A29: 2.8 | B29: Total Number & Value of Susu balances by Persons with Special needs(PWDS) | C29: Total Number of PWDS savers during the reporting period

Sheet Top Largest Depositors
A1: ='Profit & Loss Statement'!A1:D1 -> GHANA CO-OPERATIVE SUSU COLLECTORS ASSOCIATION | E1: =SUM(D4:D10) +IF(E12=0,1,0) -> 0 | F1: =IF(SUM(D4:D10)>0,"Error!", IF(D15=0,"Error!", IF(D16=0,"Error!", "")))
A2: ='Profit & Loss Statement'!A2:D2 -> MEMBERS REPORTING TEMPLATE
B4: MEMBER NAME: | C4: =IF('Profit & Loss Statement'!C4 = "", "", 'Profit & Loss Statement'!C4) -> QUICK RETURNS SUSU ENTERPRISE | D4: =IF(C4="",1,IF(ISTEXT(C4),0,1))+IF(OR(ISNUMBER(LEFT(C4)),LEFT(C4)=" "),1,0) -> 0
B5: MEMBER CODE: | C5: =IF('Profit & Loss Statement'!C5 = "", "", 'Profit & Loss Statement'!C5) -> GCSCA-GT-0-0000288 | D5: =IF(C5="",1,IF(ISTEXT(C5),0,1))+IF(OR(ISNUMBER(LEFT(C5)),LEFT(C5)=" "),1,0) -> 0
B6: RETURN CODE: | C6: =IF('Profit & Loss Statement'!C6 = "", "", 'Profit & Loss Statement'!C6) -> GCSCA-PR-UA | D6: =IF(C6="",1,IF(ISTEXT(C6),0,1)) -> 0
B7: REPORTING PERIOD | C7: =IF('Profit & Loss Statement'!C7 = "", "", 'Profit & Loss Statement'!C7) -> JUNE | D7: =IF(C7="",1,IF(ISTEXT(C7),0,1)) -> 0
B8: REPORTING DATE | C8: =IF('Profit & Loss Statement'!C8 = "", "", 'Profit & Loss Statement'!C8) -> July 2026 | D8: =IF(C8="",1, 0) -> 0
B9: YEAR | C9: ='Profit & Loss Statement'!C9 -> 2026 | D9: =IF(C9="",1, 0) -> 0
B10: REGION | C10: =IF('Profit & Loss Statement'!C10 = "", "", 'Profit & Loss Statement'!C10) -> Greater Accra-GA | D10: =IF(C10="",1, 0) -> 0
B12: Top Twenty (20) Largest Depositors | E12: =SUM(E15:E34) -> 27345 | F12: =IF(E12="","Error!", IF(E12=0, "Error!", ""))
B13: =UPPER("Top 20 Largest Depositors") -> TOP 20 LARGEST DEPOSITORS
A14: No. | B14: Customer Name | C14: Contact (Number) | D14: Location | E14: Susu Balance (GHS) | F14: Account Status | G14: Remarks
A15: 1 | B15: AGNES | D15: SOWUTUOM | E15: 2500 | F15: Active
A16: 2 | B16: LINA OTUA ACHEAMPONG | D16: SOWUTUOM | E16: 1100 | F16: Active
A17: 3 | B17: ABIGAIL YEVUGA | D17: SOWUTUOM | E17: 3050
A18: 4 | B18: AKOSUA REBECCA | D18: SOWUTUOM | E18: 560 | F18: Active
A19: 5 | B19: ADWOA AND SARAH | D19: SOWUTUOM | E19: 1250 | F19: Active
A20: 6 | B20: AUGUSTINA OBENG | D20: SOWUTUOM | E20: 700 | F20: Active
A21: 7 | B21: COMFORT ADWOA | D21: SOWUTUOM | E21: 4000 | F21: Active
A22: 8 | B22: DD 2 | D22: SOWUTUOM | E22: 1760 | F22: Active
A23: 9 | B23: DD 1 | D23: SOWUTUOM | E23: 820 | F23: Active
A24: 10 | B24: DORIS BOANSI | D24: SOWUTUOM | E24: 500 | F24: Active
A25: 11 | B25: DORCAS KRAMPAH | D25: SOWUTUOM | E25: 550 | F25: Active
A26: 12 | B26: DERRICK MENSAH | D26: SOWUTUOM | E26: 205 | F26: Active
A27: 13 | B27: ESTHER ANOKYEWAA | D27: SOWUTUOM | E27: 1580 | F27: Active
A28: 14 | B28: ISAAC ANTHONY | D28: SOWUTUOM | E28: 1700 | F28: Active
A29: 15 | B29: MARY ACHIAA | D29: SOWUTUOM | E29: 1250 | F29: Active
... A34: 20 | B34: ROYAL KITCHEN | D34: SOWUTUOM | E34: 1500 | F34: Active
B37: Top Twenty (20) Smallest Depositors | E37: =SUM(E40:E59) -> 3516
B38: =UPPER("Top 20 Smallest Depositors") -> TOP 20 SMALLEST DEPOSITORS
A39: No. | B39: Customer Name | C39: Contact (Number) | D39: Location | E39: Susu Balance (GHS) | F39: Account Status | G39: Remarks
A40: 1 | B40: PATIENCE AGYEI | D40: SOWUTUOM | E40: 140 | F40: Active
A41: 2 | B41: AMISSAH CHARLOTTE | D41: SOWUTUOM | E41: 260 | F41: Active
A42: 3 | B42: ASARE EBEN | D42: SOWUTUOM | E42: 400 | F42: Active
A43: 4 | B43: AKUA AMPONSAH | D43: SOWUTUOM | E43: 275 | F43: Active
A44: 5 | B44: AISHA IBRAHIM 2 | D44: SOWUTUOM | E44: 140 | F44: Active
A45: 6 | B45: ALICE OSEI | D45: SOWUTUOM | E45: 360 | F45: Active
A46: 7 | B46: ANGELINA ASANTEWAA | D46: SOWUTUOM | E46: 290 | F46: Active
A47: 8 | B47: GOLDDUST A KONADU | D47: SOWUTUOM | E47: 310 | F47: Active
A48: 9 | B48: HORLAS CUIZINE | D48: SOWUTUOM | E48: 350 | F48: Active
...

Sheet Ratios
A2: NO. | B2: PARAMETER/ INDICATOR | C2: Definition/ formula for the ratio | D2: Calculated Ratios
B3: PROFITABILITY & SUSTAINABILITY
B4: Return on Assets | C4: Net Operating income after taxes Total Assets | D4: =IFERROR('Profit & Loss Statement'!D28/'Balance Sheet'!D20, 0) -> 0.0027993249
B5: Return on Equity | C5: Net Operating income after taxes Total Equity | D5: =IFERROR('Profit & Loss Statement'!D28/'Balance Sheet'!D35, 0) -> 0.0036883399
B6: Return on Earning Assets | C6: Net Operating income after taxes Short term Investment+Long term Investment | D6: =IFERROR('Profit & Loss Statement'!D28/('Balance Sheet'!D14+'Balance Sheet'!D16),0) -> 0.12099667
B7: Operational Sustainability (OSS) expressed as percentage | C7: Operating Income Financing Costs+ Operating Costs | D7: =IFERROR('Profit & Loss Statement'!D16/('Profit & Loss Statement'!D17+'Profit & Loss Statement'!D22),0) -> 1.1770683
B8: Net Profit Margin | C8: Net income after tax Total Revenue | D8: =IFERROR('Profit & Loss Statement'!D28/('Profit & Loss Statement'!D16),0) -> 0.15043162
B9: LIQUIDITY
B10: Liquid Assets to Total Assets | C10: Cash and Due from Bank Short term+Long term Investment Total Assets | D10: =IFERROR(('Balance Sheet'!D13+'Balance Sheet'!D14+'Balance Sheet'!D16)/'Balance Sheet'!D20,0) -> 0.45419264
B11: PPE to Total Assets | C11: Net Fixed Assets Total Assets | D11: =IFERROR(('Balance Sheet'!D19/'Balance Sheet'!D20),0) -> 0.54580736
B12: Primary Reserve (50% Minimum) | C12: Cash and Due from Bank Susu savings/deposits | D12: =IFERROR('Balance Sheet'!D13/'Balance Sheet'!D22,0) -> 1.788367
B13: Secondary Reserve (50% Minimum) | C13: Cash and Due from Bank Short term+Long term Investment Susu savings/deposits | D13: =IFERROR(('Balance Sheet'!D13+'Balance Sheet'!D14+'Balance Sheet'!D16)/('Balance Sheet'!D22),0) -> 1.8843516
B14: Gearing ratio | C14: Total Borrowings Equity | D14: =IFERROR('Balance Sheet'!D25/'Balance Sheet'!D35,0) -> 0
B15: Borrowings to Total Assets | C15: Total Borrowings Total Assets | D15: =IFERROR('Balance Sheet'!D25/'Balance Sheet'!D20, 0) -> 0
A16: FS11 | B16: Liquid Ratio | C16: (Cash +Trade Investments)/Susu Balance +Short-term Borrowings+Interest Payable on Funding Liabilities +Accounts Payable and Other Short-term Liabilities | D16: =IFERROR(('Balance Sheet'!D13+'Balance Sheet'!D14)/('Balance Sheet'!D22+'Balance Sheet'!D23+'Balance Sheet'!D26+'Balance Sheet'!D27),0) -> 1.8843516
B17: ASSETS/ LIABILITY MANAGEMENT & FINANCIAL STRUCTURE
A18: FS1 | B18: Total Asset | D18: ='Balance Sheet'!D20 -> 129670.55
B19: Earning Asset to Total Asset ratio | C19: Short term+Long term Investment Total Assets | D19: =IFERROR(('Balance Sheet'!D14+'Balance Sheet'!D16)/'Balance Sheet'!D20,0) -> 0.023135554
A20: FS2 | B20: Capital to Assets Ratio | C20: Total Equity Total Assets | D20: =IFERROR('Balance Sheet'!D35/'Balance Sheet'!D20,0) -> 0.75896609
B21: 20 Largest deposits to Susu/savings balance Ratio | D21: =IFERROR('Top Largest Depositors'!E12/'Deposits Portfolio'!E16,0) -> 0.87490002
A22: FS4 | B22: Debt to Equity Ratio | C22: Total Liabilities Total Equity | D22: =IFERROR('Balance Sheet'!D28/'Balance Sheet'!D35,0) -> 0.31758193
A23: FS6 | B23: Yield on Susu/savings balance | C23: Cash Received from Fees and Commissions on Savings/Susu Susu/Saving balance | D23: =IFERROR(('Profit & Loss Statement'!D13+'Profit & Loss Statement'!D15)/'Balance Sheet'!D22,0) -> 0.061110222
A24: FS8 | B24: Yield on Investments | C24: Cash Received from Fees and Commissions on Investments Average Investments | D24: =IFERROR(('Profit & Loss Statement'!D14/('Balance Sheet'!D14+'Balance Sheet'!D16)),0) -> 0.16766333
B25: EFFICIENCY
A26: E1 | B26: Operating Expenses Ratio | C26: Operating Expense Total Revenue | D26: =IFERROR('Profit & Loss Statement'!D22/'Profit & Loss Statement'!D16,0) -> 0.84956838
A27: E2 | B27: Personnel Expense Ratio | C27: Personnel Expense Total Revenue | D27: =IFERROR('Profit & Loss Statement'!D19/'Profit & Loss Statement'!D16,0) -> 0
A28: E3 | B28: Administrative Expense Ratio | C28: Administrative Expense Total Revenue | D28: =IFERROR(('Profit & Loss Statement'!D20+'Profit & Loss Statement'!D21)/'Profit & Loss Statement'!D16,0) -> 0.84956838
A29: E4 | B29: Cost Income Ratio | C29: Operating Expense+Financial Exp+NonOperating Exp+ Tax Total Revenue | D29: =IFERROR((('Profit & Loss Statement'!D17+'Profit & Loss Statement'!D22-'Profit & Loss Statement'!D25+'Profit & Loss Statement'!D27)/('Profit & Loss Statement'!D16+'Profit & Loss Statement'!D24)),0) -> 0.84956838
B30: PRODUCTIVITY
A31: P1 | B31: Susu savers per Mobile Banker | C31: Number of Susu savers Number of mobile bankers | D31: =IFERROR('Deposits Portfolio'!D16/'Outreach & Social Performance'!D18,0) -> 190
A32: P2 | B32: Susu savers per Staff | C32: Number of Susu savers Number of staff | D32: =IFERROR('Deposits Portfolio'!D16/'Outreach & Social Performance'!D15,0) -> 126.66667
